2016-07-06 15:44:18,647 [Thread-2:139698802128640] [django.request:256] [base:handle_uncaught_exception] [ERROR]- Internal Server Error: /
Traceback (most recent call last):
  File "/home/xiaozhiqi/blog_env/lib/python2.7/site-packages/django/core/handlers/base.py", line 119, in get_response
    resolver_match = resolver.resolve(request.path_info)
  File "/home/xiaozhiqi/blog_env/lib/python2.7/site-packages/django/core/urlresolvers.py", line 366, in resolve
    for pattern in self.url_patterns:
  File "/home/xiaozhiqi/blog_env/lib/python2.7/site-packages/django/core/urlresolvers.py", line 402, in url_patterns
    patterns = getattr(self.urlconf_module, "urlpatterns", self.urlconf_module)
  File "/home/xiaozhiqi/blog_env/lib/python2.7/site-packages/django/core/urlresolvers.py", line 396, in urlconf_module
    self._urlconf_module = import_module(self.urlconf_name)
  File "/home/xiaozhiqi/.pyenv/versions/2.7.11/lib/python2.7/importlib/__init__.py", line 37, in import_module
    __import__(name)
  File "/home/xiaozhiqi/workplace/blog_project/blog_project/urls.py", line 18, in <module>
    from blog import views
  File "/home/xiaozhiqi/workplace/blog_project/blog/views.py", line 3
SyntaxError: Non-ASCII character '\xe9' in file /home/xiaozhiqi/workplace/blog_project/blog/views.py on line 3, but no encoding declared; see http://python.org/dev/peps/pep-0263/ for details
2016-07-08 10:36:27,753 [Thread-5:139911931643648] [django.request:170] [base:get_response] [WARNING]- Not Found: /favicon.ico
2016-07-08 11:18:34,893 [Thread-2:140631428749056] [django.request:256] [base:handle_uncaught_exception] [ERROR]- Internal Server Error: /admin/blog/article/add/
Traceback (most recent call last):
  File "/home/xiaozhiqi/blog_env/lib/python2.7/site-packages/django/core/handlers/base.py", line 132, in get_response
    response = wrapped_callback(request, *callback_args, **callback_kwargs)
  File "/home/xiaozhiqi/blog_env/lib/python2.7/site-packages/django/contrib/admin/options.py", line 616, in wrapper
    return self.admin_site.admin_view(view)(*args, **kwargs)
  File "/home/xiaozhiqi/blog_env/lib/python2.7/site-packages/django/utils/decorators.py", line 110, in _wrapped_view
    response = view_func(request, *args, **kwargs)
  File "/home/xiaozhiqi/blog_env/lib/python2.7/site-packages/django/views/decorators/cache.py", line 57, in _wrapped_view_func
    response = view_func(request, *args, **kwargs)
  File "/home/xiaozhiqi/blog_env/lib/python2.7/site-packages/django/contrib/admin/sites.py", line 233, in inner
    return view(request, *args, **kwargs)
  File "/home/xiaozhiqi/blog_env/lib/python2.7/site-packages/django/contrib/admin/options.py", line 1516, in add_view
    return self.changeform_view(request, None, form_url, extra_context)
  File "/home/xiaozhiqi/blog_env/lib/python2.7/site-packages/django/utils/decorators.py", line 34, in _wrapper
    return bound_func(*args, **kwargs)
  File "/home/xiaozhiqi/blog_env/lib/python2.7/site-packages/django/utils/decorators.py", line 110, in _wrapped_view
    response = view_func(request, *args, **kwargs)
  File "/home/xiaozhiqi/blog_env/lib/python2.7/site-packages/django/utils/decorators.py", line 30, in bound_func
    return func.__get__(self, type(self))(*args2, **kwargs2)
  File "/home/xiaozhiqi/blog_env/lib/python2.7/site-packages/django/utils/decorators.py", line 145, in inner
    return func(*args, **kwargs)
  File "/home/xiaozhiqi/blog_env/lib/python2.7/site-packages/django/contrib/admin/options.py", line 1456, in changeform_view
    ModelForm = self.get_form(request, obj)
  File "/home/xiaozhiqi/blog_env/lib/python2.7/site-packages/django/contrib/admin/options.py", line 703, in get_form
    % (e, self.__class__.__name__))
FieldError: Unknown field(s) (date_publish) specified for Article. Check fields/fieldsets/exclude attributes of class ArticleAdmin.
2016-07-08 11:18:37,039 [Thread-3:140631428749056] [django.request:256] [base:handle_uncaught_exception] [ERROR]- Internal Server Error: /admin/blog/article/add/
Traceback (most recent call last):
  File "/home/xiaozhiqi/blog_env/lib/python2.7/site-packages/django/core/handlers/base.py", line 132, in get_response
    response = wrapped_callback(request, *callback_args, **callback_kwargs)
  File "/home/xiaozhiqi/blog_env/lib/python2.7/site-packages/django/contrib/admin/options.py", line 616, in wrapper
    return self.admin_site.admin_view(view)(*args, **kwargs)
  File "/home/xiaozhiqi/blog_env/lib/python2.7/site-packages/django/utils/decorators.py", line 110, in _wrapped_view
    response = view_func(request, *args, **kwargs)
  File "/home/xiaozhiqi/blog_env/lib/python2.7/site-packages/django/views/decorators/cache.py", line 57, in _wrapped_view_func
    response = view_func(request, *args, **kwargs)
  File "/home/xiaozhiqi/blog_env/lib/python2.7/site-packages/django/contrib/admin/sites.py", line 233, in inner
    return view(request, *args, **kwargs)
  File "/home/xiaozhiqi/blog_env/lib/python2.7/site-packages/django/contrib/admin/options.py", line 1516, in add_view
    return self.changeform_view(request, None, form_url, extra_context)
  File "/home/xiaozhiqi/blog_env/lib/python2.7/site-packages/django/utils/decorators.py", line 34, in _wrapper
    return bound_func(*args, **kwargs)
  File "/home/xiaozhiqi/blog_env/lib/python2.7/site-packages/django/utils/decorators.py", line 110, in _wrapped_view
    response = view_func(request, *args, **kwargs)
  File "/home/xiaozhiqi/blog_env/lib/python2.7/site-packages/django/utils/decorators.py", line 30, in bound_func
    return func.__get__(self, type(self))(*args2, **kwargs2)
  File "/home/xiaozhiqi/blog_env/lib/python2.7/site-packages/django/utils/decorators.py", line 145, in inner
    return func(*args, **kwargs)
  File "/home/xiaozhiqi/blog_env/lib/python2.7/site-packages/django/contrib/admin/options.py", line 1456, in changeform_view
    ModelForm = self.get_form(request, obj)
  File "/home/xiaozhiqi/blog_env/lib/python2.7/site-packages/django/contrib/admin/options.py", line 703, in get_form
    % (e, self.__class__.__name__))
FieldError: Unknown field(s) (date_publish) specified for Article. Check fields/fieldsets/exclude attributes of class ArticleAdmin.
2016-07-08 11:19:11,106 [Thread-2:140110232065792] [django.request:256] [base:handle_uncaught_exception] [ERROR]- Internal Server Error: /admin/blog/article/add/
Traceback (most recent call last):
  File "/home/xiaozhiqi/blog_env/lib/python2.7/site-packages/django/core/handlers/base.py", line 132, in get_response
    response = wrapped_callback(request, *callback_args, **callback_kwargs)
  File "/home/xiaozhiqi/blog_env/lib/python2.7/site-packages/django/contrib/admin/options.py", line 616, in wrapper
    return self.admin_site.admin_view(view)(*args, **kwargs)
  File "/home/xiaozhiqi/blog_env/lib/python2.7/site-packages/django/utils/decorators.py", line 110, in _wrapped_view
    response = view_func(request, *args, **kwargs)
  File "/home/xiaozhiqi/blog_env/lib/python2.7/site-packages/django/views/decorators/cache.py", line 57, in _wrapped_view_func
    response = view_func(request, *args, **kwargs)
  File "/home/xiaozhiqi/blog_env/lib/python2.7/site-packages/django/contrib/admin/sites.py", line 233, in inner
    return view(request, *args, **kwargs)
  File "/home/xiaozhiqi/blog_env/lib/python2.7/site-packages/django/contrib/admin/options.py", line 1516, in add_view
    return self.changeform_view(request, None, form_url, extra_context)
  File "/home/xiaozhiqi/blog_env/lib/python2.7/site-packages/django/utils/decorators.py", line 34, in _wrapper
    return bound_func(*args, **kwargs)
  File "/home/xiaozhiqi/blog_env/lib/python2.7/site-packages/django/utils/decorators.py", line 110, in _wrapped_view
    response = view_func(request, *args, **kwargs)
  File "/home/xiaozhiqi/blog_env/lib/python2.7/site-packages/django/utils/decorators.py", line 30, in bound_func
    return func.__get__(self, type(self))(*args2, **kwargs2)
  File "/home/xiaozhiqi/blog_env/lib/python2.7/site-packages/django/utils/decorators.py", line 145, in inner
    return func(*args, **kwargs)
  File "/home/xiaozhiqi/blog_env/lib/python2.7/site-packages/django/contrib/admin/options.py", line 1456, in changeform_view
    ModelForm = self.get_form(request, obj)
  File "/home/xiaozhiqi/blog_env/lib/python2.7/site-packages/django/contrib/admin/options.py", line 703, in get_form
    % (e, self.__class__.__name__))
FieldError: Unknown field(s) (date_publish) specified for Article. Check fields/fieldsets/exclude attributes of class ArticleAdmin.
2016-07-08 11:19:20,365 [Thread-7:140110232065792] [django.request:256] [base:handle_uncaught_exception] [ERROR]- Internal Server Error: /admin/blog/article/add/
Traceback (most recent call last):
  File "/home/xiaozhiqi/blog_env/lib/python2.7/site-packages/django/core/handlers/base.py", line 132, in get_response
    response = wrapped_callback(request, *callback_args, **callback_kwargs)
  File "/home/xiaozhiqi/blog_env/lib/python2.7/site-packages/django/contrib/admin/options.py", line 616, in wrapper
    return self.admin_site.admin_view(view)(*args, **kwargs)
  File "/home/xiaozhiqi/blog_env/lib/python2.7/site-packages/django/utils/decorators.py", line 110, in _wrapped_view
    response = view_func(request, *args, **kwargs)
  File "/home/xiaozhiqi/blog_env/lib/python2.7/site-packages/django/views/decorators/cache.py", line 57, in _wrapped_view_func
    response = view_func(request, *args, **kwargs)
  File "/home/xiaozhiqi/blog_env/lib/python2.7/site-packages/django/contrib/admin/sites.py", line 233, in inner
    return view(request, *args, **kwargs)
  File "/home/xiaozhiqi/blog_env/lib/python2.7/site-packages/django/contrib/admin/options.py", line 1516, in add_view
    return self.changeform_view(request, None, form_url, extra_context)
  File "/home/xiaozhiqi/blog_env/lib/python2.7/site-packages/django/utils/decorators.py", line 34, in _wrapper
    return bound_func(*args, **kwargs)
  File "/home/xiaozhiqi/blog_env/lib/python2.7/site-packages/django/utils/decorators.py", line 110, in _wrapped_view
    response = view_func(request, *args, **kwargs)
  File "/home/xiaozhiqi/blog_env/lib/python2.7/site-packages/django/utils/decorators.py", line 30, in bound_func
    return func.__get__(self, type(self))(*args2, **kwargs2)
  File "/home/xiaozhiqi/blog_env/lib/python2.7/site-packages/django/utils/decorators.py", line 145, in inner
    return func(*args, **kwargs)
  File "/home/xiaozhiqi/blog_env/lib/python2.7/site-packages/django/contrib/admin/options.py", line 1456, in changeform_view
    ModelForm = self.get_form(request, obj)
  File "/home/xiaozhiqi/blog_env/lib/python2.7/site-packages/django/contrib/admin/options.py", line 703, in get_form
    % (e, self.__class__.__name__))
FieldError: Unknown field(s) (date_publish) specified for Article. Check fields/fieldsets/exclude attributes of class ArticleAdmin.
2016-07-08 11:19:34,544 [Thread-2:140590477760256] [django.request:256] [base:handle_uncaught_exception] [ERROR]- Internal Server Error: /admin/blog/article/add/
Traceback (most recent call last):
  File "/home/xiaozhiqi/blog_env/lib/python2.7/site-packages/django/core/handlers/base.py", line 132, in get_response
    response = wrapped_callback(request, *callback_args, **callback_kwargs)
  File "/home/xiaozhiqi/blog_env/lib/python2.7/site-packages/django/contrib/admin/options.py", line 616, in wrapper
    return self.admin_site.admin_view(view)(*args, **kwargs)
  File "/home/xiaozhiqi/blog_env/lib/python2.7/site-packages/django/utils/decorators.py", line 110, in _wrapped_view
    response = view_func(request, *args, **kwargs)
  File "/home/xiaozhiqi/blog_env/lib/python2.7/site-packages/django/views/decorators/cache.py", line 57, in _wrapped_view_func
    response = view_func(request, *args, **kwargs)
  File "/home/xiaozhiqi/blog_env/lib/python2.7/site-packages/django/contrib/admin/sites.py", line 233, in inner
    return view(request, *args, **kwargs)
  File "/home/xiaozhiqi/blog_env/lib/python2.7/site-packages/django/contrib/admin/options.py", line 1516, in add_view
    return self.changeform_view(request, None, form_url, extra_context)
  File "/home/xiaozhiqi/blog_env/lib/python2.7/site-packages/django/utils/decorators.py", line 34, in _wrapper
    return bound_func(*args, **kwargs)
  File "/home/xiaozhiqi/blog_env/lib/python2.7/site-packages/django/utils/decorators.py", line 110, in _wrapped_view
    response = view_func(request, *args, **kwargs)
  File "/home/xiaozhiqi/blog_env/lib/python2.7/site-packages/django/utils/decorators.py", line 30, in bound_func
    return func.__get__(self, type(self))(*args2, **kwargs2)
  File "/home/xiaozhiqi/blog_env/lib/python2.7/site-packages/django/utils/decorators.py", line 145, in inner
    return func(*args, **kwargs)
  File "/home/xiaozhiqi/blog_env/lib/python2.7/site-packages/django/contrib/admin/options.py", line 1456, in changeform_view
    ModelForm = self.get_form(request, obj)
  File "/home/xiaozhiqi/blog_env/lib/python2.7/site-packages/django/contrib/admin/options.py", line 703, in get_form
    % (e, self.__class__.__name__))
FieldError: Unknown field(s) (date_publish) specified for Article. Check fields/fieldsets/exclude attributes of class ArticleAdmin.
2016-07-08 11:19:35,950 [Thread-3:140590477760256] [django.request:256] [base:handle_uncaught_exception] [ERROR]- Internal Server Error: /admin/blog/article/add/
Traceback (most recent call last):
  File "/home/xiaozhiqi/blog_env/lib/python2.7/site-packages/django/core/handlers/base.py", line 132, in get_response
    response = wrapped_callback(request, *callback_args, **callback_kwargs)
  File "/home/xiaozhiqi/blog_env/lib/python2.7/site-packages/django/contrib/admin/options.py", line 616, in wrapper
    return self.admin_site.admin_view(view)(*args, **kwargs)
  File "/home/xiaozhiqi/blog_env/lib/python2.7/site-packages/django/utils/decorators.py", line 110, in _wrapped_view
    response = view_func(request, *args, **kwargs)
  File "/home/xiaozhiqi/blog_env/lib/python2.7/site-packages/django/views/decorators/cache.py", line 57, in _wrapped_view_func
    response = view_func(request, *args, **kwargs)
  File "/home/xiaozhiqi/blog_env/lib/python2.7/site-packages/django/contrib/admin/sites.py", line 233, in inner
    return view(request, *args, **kwargs)
  File "/home/xiaozhiqi/blog_env/lib/python2.7/site-packages/django/contrib/admin/options.py", line 1516, in add_view
    return self.changeform_view(request, None, form_url, extra_context)
  File "/home/xiaozhiqi/blog_env/lib/python2.7/site-packages/django/utils/decorators.py", line 34, in _wrapper
    return bound_func(*args, **kwargs)
  File "/home/xiaozhiqi/blog_env/lib/python2.7/site-packages/django/utils/decorators.py", line 110, in _wrapped_view
    response = view_func(request, *args, **kwargs)
  File "/home/xiaozhiqi/blog_env/lib/python2.7/site-packages/django/utils/decorators.py", line 30, in bound_func
    return func.__get__(self, type(self))(*args2, **kwargs2)
  File "/home/xiaozhiqi/blog_env/lib/python2.7/site-packages/django/utils/decorators.py", line 145, in inner
    return func(*args, **kwargs)
  File "/home/xiaozhiqi/blog_env/lib/python2.7/site-packages/django/contrib/admin/options.py", line 1456, in changeform_view
    ModelForm = self.get_form(request, obj)
  File "/home/xiaozhiqi/blog_env/lib/python2.7/site-packages/django/contrib/admin/options.py", line 703, in get_form
    % (e, self.__class__.__name__))
FieldError: Unknown field(s) (date_publish) specified for Article. Check fields/fieldsets/exclude attributes of class ArticleAdmin.
2016-07-08 11:19:36,738 [Thread-4:140590477760256] [django.request:256] [base:handle_uncaught_exception] [ERROR]- Internal Server Error: /admin/blog/article/add/
Traceback (most recent call last):
  File "/home/xiaozhiqi/blog_env/lib/python2.7/site-packages/django/core/handlers/base.py", line 132, in get_response
    response = wrapped_callback(request, *callback_args, **callback_kwargs)
  File "/home/xiaozhiqi/blog_env/lib/python2.7/site-packages/django/contrib/admin/options.py", line 616, in wrapper
    return self.admin_site.admin_view(view)(*args, **kwargs)
  File "/home/xiaozhiqi/blog_env/lib/python2.7/site-packages/django/utils/decorators.py", line 110, in _wrapped_view
    response = view_func(request, *args, **kwargs)
  File "/home/xiaozhiqi/blog_env/lib/python2.7/site-packages/django/views/decorators/cache.py", line 57, in _wrapped_view_func
    response = view_func(request, *args, **kwargs)
  File "/home/xiaozhiqi/blog_env/lib/python2.7/site-packages/django/contrib/admin/sites.py", line 233, in inner
    return view(request, *args, **kwargs)
  File "/home/xiaozhiqi/blog_env/lib/python2.7/site-packages/django/contrib/admin/options.py", line 1516, in add_view
    return self.changeform_view(request, None, form_url, extra_context)
  File "/home/xiaozhiqi/blog_env/lib/python2.7/site-packages/django/utils/decorators.py", line 34, in _wrapper
    return bound_func(*args, **kwargs)
  File "/home/xiaozhiqi/blog_env/lib/python2.7/site-packages/django/utils/decorators.py", line 110, in _wrapped_view
    response = view_func(request, *args, **kwargs)
  File "/home/xiaozhiqi/blog_env/lib/python2.7/site-packages/django/utils/decorators.py", line 30, in bound_func
    return func.__get__(self, type(self))(*args2, **kwargs2)
  File "/home/xiaozhiqi/blog_env/lib/python2.7/site-packages/django/utils/decorators.py", line 145, in inner
    return func(*args, **kwargs)
  File "/home/xiaozhiqi/blog_env/lib/python2.7/site-packages/django/contrib/admin/options.py", line 1456, in changeform_view
    ModelForm = self.get_form(request, obj)
  File "/home/xiaozhiqi/blog_env/lib/python2.7/site-packages/django/contrib/admin/options.py", line 703, in get_form
    % (e, self.__class__.__name__))
FieldError: Unknown field(s) (date_publish) specified for Article. Check fields/fieldsets/exclude attributes of class ArticleAdmin.
2016-07-08 11:19:37,460 [Thread-5:140590477760256] [django.request:256] [base:handle_uncaught_exception] [ERROR]- Internal Server Error: /admin/blog/article/add/
Traceback (most recent call last):
  File "/home/xiaozhiqi/blog_env/lib/python2.7/site-packages/django/core/handlers/base.py", line 132, in get_response
    response = wrapped_callback(request, *callback_args, **callback_kwargs)
  File "/home/xiaozhiqi/blog_env/lib/python2.7/site-packages/django/contrib/admin/options.py", line 616, in wrapper
    return self.admin_site.admin_view(view)(*args, **kwargs)
  File "/home/xiaozhiqi/blog_env/lib/python2.7/site-packages/django/utils/decorators.py", line 110, in _wrapped_view
    response = view_func(request, *args, **kwargs)
  File "/home/xiaozhiqi/blog_env/lib/python2.7/site-packages/django/views/decorators/cache.py", line 57, in _wrapped_view_func
    response = view_func(request, *args, **kwargs)
  File "/home/xiaozhiqi/blog_env/lib/python2.7/site-packages/django/contrib/admin/sites.py", line 233, in inner
    return view(request, *args, **kwargs)
  File "/home/xiaozhiqi/blog_env/lib/python2.7/site-packages/django/contrib/admin/options.py", line 1516, in add_view
    return self.changeform_view(request, None, form_url, extra_context)
  File "/home/xiaozhiqi/blog_env/lib/python2.7/site-packages/django/utils/decorators.py", line 34, in _wrapper
    return bound_func(*args, **kwargs)
  File "/home/xiaozhiqi/blog_env/lib/python2.7/site-packages/django/utils/decorators.py", line 110, in _wrapped_view
    response = view_func(request, *args, **kwargs)
  File "/home/xiaozhiqi/blog_env/lib/python2.7/site-packages/django/utils/decorators.py", line 30, in bound_func
    return func.__get__(self, type(self))(*args2, **kwargs2)
  File "/home/xiaozhiqi/blog_env/lib/python2.7/site-packages/django/utils/decorators.py", line 145, in inner
    return func(*args, **kwargs)
  File "/home/xiaozhiqi/blog_env/lib/python2.7/site-packages/django/contrib/admin/options.py", line 1456, in changeform_view
    ModelForm = self.get_form(request, obj)
  File "/home/xiaozhiqi/blog_env/lib/python2.7/site-packages/django/contrib/admin/options.py", line 703, in get_form
    % (e, self.__class__.__name__))
FieldError: Unknown field(s) (date_publish) specified for Article. Check fields/fieldsets/exclude attributes of class ArticleAdmin.
2016-07-08 11:30:31,517 [Thread-15:139920386221824] [django.request:256] [base:handle_uncaught_exception] [ERROR]- Internal Server Error: /admin/blog/article/add/
Traceback (most recent call last):
  File "/home/xiaozhiqi/blog_env/lib/python2.7/site-packages/django/core/handlers/base.py", line 132, in get_response
    response = wrapped_callback(request, *callback_args, **callback_kwargs)
  File "/home/xiaozhiqi/blog_env/lib/python2.7/site-packages/django/contrib/admin/options.py", line 616, in wrapper
    return self.admin_site.admin_view(view)(*args, **kwargs)
  File "/home/xiaozhiqi/blog_env/lib/python2.7/site-packages/django/utils/decorators.py", line 110, in _wrapped_view
    response = view_func(request, *args, **kwargs)
  File "/home/xiaozhiqi/blog_env/lib/python2.7/site-packages/django/views/decorators/cache.py", line 57, in _wrapped_view_func
    response = view_func(request, *args, **kwargs)
  File "/home/xiaozhiqi/blog_env/lib/python2.7/site-packages/django/contrib/admin/sites.py", line 233, in inner
    return view(request, *args, **kwargs)
  File "/home/xiaozhiqi/blog_env/lib/python2.7/site-packages/django/contrib/admin/options.py", line 1516, in add_view
    return self.changeform_view(request, None, form_url, extra_context)
  File "/home/xiaozhiqi/blog_env/lib/python2.7/site-packages/django/utils/decorators.py", line 34, in _wrapper
    return bound_func(*args, **kwargs)
  File "/home/xiaozhiqi/blog_env/lib/python2.7/site-packages/django/utils/decorators.py", line 110, in _wrapped_view
    response = view_func(request, *args, **kwargs)
  File "/home/xiaozhiqi/blog_env/lib/python2.7/site-packages/django/utils/decorators.py", line 30, in bound_func
    return func.__get__(self, type(self))(*args2, **kwargs2)
  File "/home/xiaozhiqi/blog_env/lib/python2.7/site-packages/django/utils/decorators.py", line 145, in inner
    return func(*args, **kwargs)
  File "/home/xiaozhiqi/blog_env/lib/python2.7/site-packages/django/contrib/admin/options.py", line 1467, in changeform_view
    self.save_model(request, new_object, form, not add)
  File "/home/xiaozhiqi/blog_env/lib/python2.7/site-packages/django/contrib/admin/options.py", line 1078, in save_model
    obj.save()
  File "/home/xiaozhiqi/blog_env/lib/python2.7/site-packages/django/db/models/base.py", line 710, in save
    force_update=force_update, update_fields=update_fields)
  File "/home/xiaozhiqi/blog_env/lib/python2.7/site-packages/django/db/models/base.py", line 738, in save_base
    updated = self._save_table(raw, cls, force_insert, force_update, using, update_fields)
  File "/home/xiaozhiqi/blog_env/lib/python2.7/site-packages/django/db/models/base.py", line 822, in _save_table
    result = self._do_insert(cls._base_manager, using, fields, update_pk, raw)
  File "/home/xiaozhiqi/blog_env/lib/python2.7/site-packages/django/db/models/base.py", line 861, in _do_insert
    using=using, raw=raw)
  File "/home/xiaozhiqi/blog_env/lib/python2.7/site-packages/django/db/models/manager.py", line 127, in manager_method
    return getattr(self.get_queryset(), name)(*args, **kwargs)
  File "/home/xiaozhiqi/blog_env/lib/python2.7/site-packages/django/db/models/query.py", line 920, in _insert
    return query.get_compiler(using=using).execute_sql(return_id)
  File "/home/xiaozhiqi/blog_env/lib/python2.7/site-packages/django/db/models/sql/compiler.py", line 974, in execute_sql
    cursor.execute(sql, params)
  File "/home/xiaozhiqi/blog_env/lib/python2.7/site-packages/django/db/backends/utils.py", line 79, in execute
    return super(CursorDebugWrapper, self).execute(sql, params)
  File "/home/xiaozhiqi/blog_env/lib/python2.7/site-packages/django/db/backends/utils.py", line 64, in execute
    return self.cursor.execute(sql, params)
  File "/home/xiaozhiqi/blog_env/lib/python2.7/site-packages/django/db/backends/mysql/base.py", line 129, in execute
    six.reraise(utils.IntegrityError, utils.IntegrityError(*tuple(e.args)), sys.exc_info()[2])
  File "/home/xiaozhiqi/blog_env/lib/python2.7/site-packages/django/db/backends/mysql/base.py", line 124, in execute
    return self.cursor.execute(query, args)
  File "/home/xiaozhiqi/blog_env/lib/python2.7/site-packages/MySQLdb/cursors.py", line 205, in execute
    self.errorhandler(self, exc, value)
  File "/home/xiaozhiqi/blog_env/lib/python2.7/site-packages/MySQLdb/connections.py", line 36, in defaulterrorhandler
    raise errorclass, errorvalue
IntegrityError: (1048, "Column 'user_id' cannot be null")
2016-07-08 11:32:27,113 [Thread-21:139920169498368] [django.request:256] [base:handle_uncaught_exception] [ERROR]- Internal Server Error: /admin/blog/article/add/
Traceback (most recent call last):
  File "/home/xiaozhiqi/blog_env/lib/python2.7/site-packages/django/core/handlers/base.py", line 132, in get_response
    response = wrapped_callback(request, *callback_args, **callback_kwargs)
  File "/home/xiaozhiqi/blog_env/lib/python2.7/site-packages/django/contrib/admin/options.py", line 616, in wrapper
    return self.admin_site.admin_view(view)(*args, **kwargs)
  File "/home/xiaozhiqi/blog_env/lib/python2.7/site-packages/django/utils/decorators.py", line 110, in _wrapped_view
    response = view_func(request, *args, **kwargs)
  File "/home/xiaozhiqi/blog_env/lib/python2.7/site-packages/django/views/decorators/cache.py", line 57, in _wrapped_view_func
    response = view_func(request, *args, **kwargs)
  File "/home/xiaozhiqi/blog_env/lib/python2.7/site-packages/django/contrib/admin/sites.py", line 233, in inner
    return view(request, *args, **kwargs)
  File "/home/xiaozhiqi/blog_env/lib/python2.7/site-packages/django/contrib/admin/options.py", line 1516, in add_view
    return self.changeform_view(request, None, form_url, extra_context)
  File "/home/xiaozhiqi/blog_env/lib/python2.7/site-packages/django/utils/decorators.py", line 34, in _wrapper
    return bound_func(*args, **kwargs)
  File "/home/xiaozhiqi/blog_env/lib/python2.7/site-packages/django/utils/decorators.py", line 110, in _wrapped_view
    response = view_func(request, *args, **kwargs)
  File "/home/xiaozhiqi/blog_env/lib/python2.7/site-packages/django/utils/decorators.py", line 30, in bound_func
    return func.__get__(self, type(self))(*args2, **kwargs2)
  File "/home/xiaozhiqi/blog_env/lib/python2.7/site-packages/django/utils/decorators.py", line 145, in inner
    return func(*args, **kwargs)
  File "/home/xiaozhiqi/blog_env/lib/python2.7/site-packages/django/contrib/admin/options.py", line 1467, in changeform_view
    self.save_model(request, new_object, form, not add)
  File "/home/xiaozhiqi/blog_env/lib/python2.7/site-packages/django/contrib/admin/options.py", line 1078, in save_model
    obj.save()
  File "/home/xiaozhiqi/blog_env/lib/python2.7/site-packages/django/db/models/base.py", line 710, in save
    force_update=force_update, update_fields=update_fields)
  File "/home/xiaozhiqi/blog_env/lib/python2.7/site-packages/django/db/models/base.py", line 738, in save_base
    updated = self._save_table(raw, cls, force_insert, force_update, using, update_fields)
  File "/home/xiaozhiqi/blog_env/lib/python2.7/site-packages/django/db/models/base.py", line 822, in _save_table
    result = self._do_insert(cls._base_manager, using, fields, update_pk, raw)
  File "/home/xiaozhiqi/blog_env/lib/python2.7/site-packages/django/db/models/base.py", line 861, in _do_insert
    using=using, raw=raw)
  File "/home/xiaozhiqi/blog_env/lib/python2.7/site-packages/django/db/models/manager.py", line 127, in manager_method
    return getattr(self.get_queryset(), name)(*args, **kwargs)
  File "/home/xiaozhiqi/blog_env/lib/python2.7/site-packages/django/db/models/query.py", line 920, in _insert
    return query.get_compiler(using=using).execute_sql(return_id)
  File "/home/xiaozhiqi/blog_env/lib/python2.7/site-packages/django/db/models/sql/compiler.py", line 974, in execute_sql
    cursor.execute(sql, params)
  File "/home/xiaozhiqi/blog_env/lib/python2.7/site-packages/django/db/backends/utils.py", line 79, in execute
    return super(CursorDebugWrapper, self).execute(sql, params)
  File "/home/xiaozhiqi/blog_env/lib/python2.7/site-packages/django/db/backends/utils.py", line 64, in execute
    return self.cursor.execute(sql, params)
  File "/home/xiaozhiqi/blog_env/lib/python2.7/site-packages/django/db/backends/mysql/base.py", line 129, in execute
    six.reraise(utils.IntegrityError, utils.IntegrityError(*tuple(e.args)), sys.exc_info()[2])
  File "/home/xiaozhiqi/blog_env/lib/python2.7/site-packages/django/db/backends/mysql/base.py", line 124, in execute
    return self.cursor.execute(query, args)
  File "/home/xiaozhiqi/blog_env/lib/python2.7/site-packages/MySQLdb/cursors.py", line 205, in execute
    self.errorhandler(self, exc, value)
  File "/home/xiaozhiqi/blog_env/lib/python2.7/site-packages/MySQLdb/connections.py", line 36, in defaulterrorhandler
    raise errorclass, errorvalue
IntegrityError: (1048, "Column 'user_id' cannot be null")
2016-07-10 15:15:15,105 [Thread-26:140711761491712] [django.request:170] [base:get_response] [WARNING]- Not Found: /uploads/2016/07/little-cat.jpg
2016-07-10 15:16:05,359 [Thread-2:140650414528256] [django.request:170] [base:get_response] [WARNING]- Not Found: /uploads/2016/07/little-cat.jpg
2016-07-10 15:16:06,139 [Thread-3:140650414528256] [django.request:170] [base:get_response] [WARNING]- Not Found: /uploads/2016/07/little-cat.jpg
2016-07-10 15:16:06,394 [Thread-4:140650414528256] [django.request:170] [base:get_response] [WARNING]- Not Found: /uploads/2016/07/little-cat.jpg
2016-07-10 15:16:06,589 [Thread-5:140650414528256] [django.request:170] [base:get_response] [WARNING]- Not Found: /uploads/2016/07/little-cat.jpg
2016-07-10 15:16:06,772 [Thread-6:140650414528256] [django.request:170] [base:get_response] [WARNING]- Not Found: /uploads/2016/07/little-cat.jpg
2016-07-10 18:32:07,637 [Thread-2:140118922954496] [django.request:256] [base:handle_uncaught_exception] [ERROR]- Internal Server Error: /
Traceback (most recent call last):
  File "/home/xiaozhiqi/blog_env/lib/python2.7/site-packages/django/core/handlers/base.py", line 132, in get_response
    response = wrapped_callback(request, *callback_args, **callback_kwargs)
  File "/home/xiaozhiqi/workplace/blog_project/blog/views.py", line 29, in index
    return render(request,'index.html',locals())
  File "/home/xiaozhiqi/blog_env/lib/python2.7/site-packages/django/shortcuts.py", line 67, in render
    template_name, context, request=request, using=using)
  File "/home/xiaozhiqi/blog_env/lib/python2.7/site-packages/django/template/loader.py", line 98, in render_to_string
    template = get_template(template_name, using=using)
  File "/home/xiaozhiqi/blog_env/lib/python2.7/site-packages/django/template/loader.py", line 35, in get_template
    return engine.get_template(template_name, dirs)
  File "/home/xiaozhiqi/blog_env/lib/python2.7/site-packages/django/template/backends/django.py", line 30, in get_template
    return Template(self.engine.get_template(template_name, dirs))
  File "/home/xiaozhiqi/blog_env/lib/python2.7/site-packages/django/template/engine.py", line 167, in get_template
    template, origin = self.find_template(template_name, dirs)
  File "/home/xiaozhiqi/blog_env/lib/python2.7/site-packages/django/template/engine.py", line 141, in find_template
    source, display_name = loader(name, dirs)
  File "/home/xiaozhiqi/blog_env/lib/python2.7/site-packages/django/template/loaders/base.py", line 13, in __call__
    return self.load_template(template_name, template_dirs)
  File "/home/xiaozhiqi/blog_env/lib/python2.7/site-packages/django/template/loaders/base.py", line 23, in load_template
    template = Template(source, origin, template_name, self.engine)
  File "/home/xiaozhiqi/blog_env/lib/python2.7/site-packages/django/template/base.py", line 190, in __init__
    self.nodelist = engine.compile_string(template_string, origin)
  File "/home/xiaozhiqi/blog_env/lib/python2.7/site-packages/django/template/engine.py", line 261, in compile_string
    return parser.parse()
  File "/home/xiaozhiqi/blog_env/lib/python2.7/site-packages/django/template/base.py", line 339, in parse
    self.invalid_block_tag(token, command, parse_until)
  File "/home/xiaozhiqi/blog_env/lib/python2.7/site-packages/django/template/base.py", line 395, in invalid_block_tag
    raise self.error(token, "Invalid block tag: '%s'" % command)
TemplateSyntaxError: Invalid block tag: 'extends'base.html''
2016-07-10 18:32:08,458 [Thread-3:140118914299648] [django.request:256] [base:handle_uncaught_exception] [ERROR]- Internal Server Error: /
Traceback (most recent call last):
  File "/home/xiaozhiqi/blog_env/lib/python2.7/site-packages/django/core/handlers/base.py", line 132, in get_response
    response = wrapped_callback(request, *callback_args, **callback_kwargs)
  File "/home/xiaozhiqi/workplace/blog_project/blog/views.py", line 29, in index
    return render(request,'index.html',locals())
  File "/home/xiaozhiqi/blog_env/lib/python2.7/site-packages/django/shortcuts.py", line 67, in render
    template_name, context, request=request, using=using)
  File "/home/xiaozhiqi/blog_env/lib/python2.7/site-packages/django/template/loader.py", line 98, in render_to_string
    template = get_template(template_name, using=using)
  File "/home/xiaozhiqi/blog_env/lib/python2.7/site-packages/django/template/loader.py", line 35, in get_template
    return engine.get_template(template_name, dirs)
  File "/home/xiaozhiqi/blog_env/lib/python2.7/site-packages/django/template/backends/django.py", line 30, in get_template
    return Template(self.engine.get_template(template_name, dirs))
  File "/home/xiaozhiqi/blog_env/lib/python2.7/site-packages/django/template/engine.py", line 167, in get_template
    template, origin = self.find_template(template_name, dirs)
  File "/home/xiaozhiqi/blog_env/lib/python2.7/site-packages/django/template/engine.py", line 141, in find_template
    source, display_name = loader(name, dirs)
  File "/home/xiaozhiqi/blog_env/lib/python2.7/site-packages/django/template/loaders/base.py", line 13, in __call__
    return self.load_template(template_name, template_dirs)
  File "/home/xiaozhiqi/blog_env/lib/python2.7/site-packages/django/template/loaders/base.py", line 23, in load_template
    template = Template(source, origin, template_name, self.engine)
  File "/home/xiaozhiqi/blog_env/lib/python2.7/site-packages/django/template/base.py", line 190, in __init__
    self.nodelist = engine.compile_string(template_string, origin)
  File "/home/xiaozhiqi/blog_env/lib/python2.7/site-packages/django/template/engine.py", line 261, in compile_string
    return parser.parse()
  File "/home/xiaozhiqi/blog_env/lib/python2.7/site-packages/django/template/base.py", line 339, in parse
    self.invalid_block_tag(token, command, parse_until)
  File "/home/xiaozhiqi/blog_env/lib/python2.7/site-packages/django/template/base.py", line 395, in invalid_block_tag
    raise self.error(token, "Invalid block tag: '%s'" % command)
TemplateSyntaxError: Invalid block tag: 'extends'base.html''
2016-07-10 18:32:08,907 [Thread-4:140118905906944] [django.request:256] [base:handle_uncaught_exception] [ERROR]- Internal Server Error: /
Traceback (most recent call last):
  File "/home/xiaozhiqi/blog_env/lib/python2.7/site-packages/django/core/handlers/base.py", line 132, in get_response
    response = wrapped_callback(request, *callback_args, **callback_kwargs)
  File "/home/xiaozhiqi/workplace/blog_project/blog/views.py", line 29, in index
    return render(request,'index.html',locals())
  File "/home/xiaozhiqi/blog_env/lib/python2.7/site-packages/django/shortcuts.py", line 67, in render
    template_name, context, request=request, using=using)
  File "/home/xiaozhiqi/blog_env/lib/python2.7/site-packages/django/template/loader.py", line 98, in render_to_string
    template = get_template(template_name, using=using)
  File "/home/xiaozhiqi/blog_env/lib/python2.7/site-packages/django/template/loader.py", line 35, in get_template
    return engine.get_template(template_name, dirs)
  File "/home/xiaozhiqi/blog_env/lib/python2.7/site-packages/django/template/backends/django.py", line 30, in get_template
    return Template(self.engine.get_template(template_name, dirs))
  File "/home/xiaozhiqi/blog_env/lib/python2.7/site-packages/django/template/engine.py", line 167, in get_template
    template, origin = self.find_template(template_name, dirs)
  File "/home/xiaozhiqi/blog_env/lib/python2.7/site-packages/django/template/engine.py", line 141, in find_template
    source, display_name = loader(name, dirs)
  File "/home/xiaozhiqi/blog_env/lib/python2.7/site-packages/django/template/loaders/base.py", line 13, in __call__
    return self.load_template(template_name, template_dirs)
  File "/home/xiaozhiqi/blog_env/lib/python2.7/site-packages/django/template/loaders/base.py", line 23, in load_template
    template = Template(source, origin, template_name, self.engine)
  File "/home/xiaozhiqi/blog_env/lib/python2.7/site-packages/django/template/base.py", line 190, in __init__
    self.nodelist = engine.compile_string(template_string, origin)
  File "/home/xiaozhiqi/blog_env/lib/python2.7/site-packages/django/template/engine.py", line 261, in compile_string
    return parser.parse()
  File "/home/xiaozhiqi/blog_env/lib/python2.7/site-packages/django/template/base.py", line 339, in parse
    self.invalid_block_tag(token, command, parse_until)
  File "/home/xiaozhiqi/blog_env/lib/python2.7/site-packages/django/template/base.py", line 395, in invalid_block_tag
    raise self.error(token, "Invalid block tag: '%s'" % command)
TemplateSyntaxError: Invalid block tag: 'extends'base.html''
2016-07-10 18:32:09,347 [Thread-5:140118897514240] [django.request:256] [base:handle_uncaught_exception] [ERROR]- Internal Server Error: /
Traceback (most recent call last):
  File "/home/xiaozhiqi/blog_env/lib/python2.7/site-packages/django/core/handlers/base.py", line 132, in get_response
    response = wrapped_callback(request, *callback_args, **callback_kwargs)
  File "/home/xiaozhiqi/workplace/blog_project/blog/views.py", line 29, in index
    return render(request,'index.html',locals())
  File "/home/xiaozhiqi/blog_env/lib/python2.7/site-packages/django/shortcuts.py", line 67, in render
    template_name, context, request=request, using=using)
  File "/home/xiaozhiqi/blog_env/lib/python2.7/site-packages/django/template/loader.py", line 98, in render_to_string
    template = get_template(template_name, using=using)
  File "/home/xiaozhiqi/blog_env/lib/python2.7/site-packages/django/template/loader.py", line 35, in get_template
    return engine.get_template(template_name, dirs)
  File "/home/xiaozhiqi/blog_env/lib/python2.7/site-packages/django/template/backends/django.py", line 30, in get_template
    return Template(self.engine.get_template(template_name, dirs))
  File "/home/xiaozhiqi/blog_env/lib/python2.7/site-packages/django/template/engine.py", line 167, in get_template
    template, origin = self.find_template(template_name, dirs)
  File "/home/xiaozhiqi/blog_env/lib/python2.7/site-packages/django/template/engine.py", line 141, in find_template
    source, display_name = loader(name, dirs)
  File "/home/xiaozhiqi/blog_env/lib/python2.7/site-packages/django/template/loaders/base.py", line 13, in __call__
    return self.load_template(template_name, template_dirs)
  File "/home/xiaozhiqi/blog_env/lib/python2.7/site-packages/django/template/loaders/base.py", line 23, in load_template
    template = Template(source, origin, template_name, self.engine)
  File "/home/xiaozhiqi/blog_env/lib/python2.7/site-packages/django/template/base.py", line 190, in __init__
    self.nodelist = engine.compile_string(template_string, origin)
  File "/home/xiaozhiqi/blog_env/lib/python2.7/site-packages/django/template/engine.py", line 261, in compile_string
    return parser.parse()
  File "/home/xiaozhiqi/blog_env/lib/python2.7/site-packages/django/template/base.py", line 339, in parse
    self.invalid_block_tag(token, command, parse_until)
  File "/home/xiaozhiqi/blog_env/lib/python2.7/site-packages/django/template/base.py", line 395, in invalid_block_tag
    raise self.error(token, "Invalid block tag: '%s'" % command)
TemplateSyntaxError: Invalid block tag: 'extends'base.html''
2016-07-10 18:32:09,737 [Thread-6:140118889121536] [django.request:256] [base:handle_uncaught_exception] [ERROR]- Internal Server Error: /
Traceback (most recent call last):
  File "/home/xiaozhiqi/blog_env/lib/python2.7/site-packages/django/core/handlers/base.py", line 132, in get_response
    response = wrapped_callback(request, *callback_args, **callback_kwargs)
  File "/home/xiaozhiqi/workplace/blog_project/blog/views.py", line 29, in index
    return render(request,'index.html',locals())
  File "/home/xiaozhiqi/blog_env/lib/python2.7/site-packages/django/shortcuts.py", line 67, in render
    template_name, context, request=request, using=using)
  File "/home/xiaozhiqi/blog_env/lib/python2.7/site-packages/django/template/loader.py", line 98, in render_to_string
    template = get_template(template_name, using=using)
  File "/home/xiaozhiqi/blog_env/lib/python2.7/site-packages/django/template/loader.py", line 35, in get_template
    return engine.get_template(template_name, dirs)
  File "/home/xiaozhiqi/blog_env/lib/python2.7/site-packages/django/template/backends/django.py", line 30, in get_template
    return Template(self.engine.get_template(template_name, dirs))
  File "/home/xiaozhiqi/blog_env/lib/python2.7/site-packages/django/template/engine.py", line 167, in get_template
    template, origin = self.find_template(template_name, dirs)
  File "/home/xiaozhiqi/blog_env/lib/python2.7/site-packages/django/template/engine.py", line 141, in find_template
    source, display_name = loader(name, dirs)
  File "/home/xiaozhiqi/blog_env/lib/python2.7/site-packages/django/template/loaders/base.py", line 13, in __call__
    return self.load_template(template_name, template_dirs)
  File "/home/xiaozhiqi/blog_env/lib/python2.7/site-packages/django/template/loaders/base.py", line 23, in load_template
    template = Template(source, origin, template_name, self.engine)
  File "/home/xiaozhiqi/blog_env/lib/python2.7/site-packages/django/template/base.py", line 190, in __init__
    self.nodelist = engine.compile_string(template_string, origin)
  File "/home/xiaozhiqi/blog_env/lib/python2.7/site-packages/django/template/engine.py", line 261, in compile_string
    return parser.parse()
  File "/home/xiaozhiqi/blog_env/lib/python2.7/site-packages/django/template/base.py", line 339, in parse
    self.invalid_block_tag(token, command, parse_until)
  File "/home/xiaozhiqi/blog_env/lib/python2.7/site-packages/django/template/base.py", line 395, in invalid_block_tag
    raise self.error(token, "Invalid block tag: '%s'" % command)
TemplateSyntaxError: Invalid block tag: 'extends'base.html''
2016-07-10 18:52:03,674 [Thread-357:140118897514240] [django.request:170] [base:get_response] [WARNING]- Not Found: /admn
2016-07-10 19:01:54,469 [Thread-12:140321874765568] [django.request:170] [base:get_response] [WARNING]- Not Found: /index.html
2016-07-10 19:01:56,217 [Thread-13:140321874765568] [django.request:170] [base:get_response] [WARNING]- Not Found: /index.html
2016-07-10 19:01:57,750 [Thread-14:140321960691456] [django.request:170] [base:get_response] [WARNING]- Not Found: /index.html
2016-07-10 19:14:02,517 [Thread-25:140365277415168] [django.request:170] [base:get_response] [WARNING]- Not Found: /329275108@qq.com
2016-07-10 22:07:11,245 [Thread-30:139784835540736] [django.request:170] [base:get_response] [WARNING]- Not Found: /ad/2016/07/a1.jpg
2016-07-10 22:07:11,283 [Thread-32:139784878028544] [django.request:170] [base:get_response] [WARNING]- Not Found: /ad/2016/07/a2.jpg
2016-07-10 22:07:11,293 [Thread-33:139784869111552] [django.request:170] [base:get_response] [WARNING]- Not Found: /ad/2016/07/a3.jpg
2016-07-10 22:07:11,318 [Thread-34:139784835540736] [django.request:170] [base:get_response] [WARNING]- Not Found: /ad/2016/07/a4.jpg
2016-07-10 22:07:11,344 [Thread-35:139784869111552] [django.request:170] [base:get_response] [WARNING]- Not Found: /ad/2016/07/a1.jpg
2016-07-10 22:07:15,640 [Thread-37:139784869111552] [django.request:170] [base:get_response] [WARNING]- Not Found: /ad/2016/07/a1.jpg
2016-07-10 22:07:15,646 [Thread-38:139784835540736] [django.request:170] [base:get_response] [WARNING]- Not Found: /ad/2016/07/a2.jpg
2016-07-10 22:07:15,651 [Thread-39:139784878028544] [django.request:170] [base:get_response] [WARNING]- Not Found: /ad/2016/07/a4.jpg
2016-07-10 22:07:15,668 [Thread-40:139784852326144] [django.request:170] [base:get_response] [WARNING]- Not Found: /ad/2016/07/a3.jpg
2016-07-10 22:07:16,609 [Thread-42:139784878028544] [django.request:170] [base:get_response] [WARNING]- Not Found: /ad/2016/07/a1.jpg
2016-07-10 22:07:16,616 [Thread-43:139784869111552] [django.request:170] [base:get_response] [WARNING]- Not Found: /ad/2016/07/a2.jpg
2016-07-10 22:07:16,630 [Thread-44:139784878028544] [django.request:170] [base:get_response] [WARNING]- Not Found: /ad/2016/07/a3.jpg
2016-07-10 22:07:16,643 [Thread-45:139784869111552] [django.request:170] [base:get_response] [WARNING]- Not Found: /ad/2016/07/a4.jpg
2016-07-10 22:08:35,880 [Thread-52:139784869111552] [django.request:170] [base:get_response] [WARNING]- Not Found: /ad/2016/07/a1.jpg
2016-07-10 22:08:35,916 [Thread-53:139784860718848] [django.request:170] [base:get_response] [WARNING]- Not Found: /ad/2016/07/a2.jpg
2016-07-10 22:08:35,924 [Thread-54:139784869111552] [django.request:170] [base:get_response] [WARNING]- Not Found: /ad/2016/07/a3.jpg
2016-07-10 22:08:35,938 [Thread-55:139784852326144] [django.request:170] [base:get_response] [WARNING]- Not Found: /ad/2016/07/a4.jpg
2016-07-10 22:11:44,104 [Thread-62:139784843933440] [django.request:256] [base:handle_uncaught_exception] [ERROR]- Internal Server Error: /
Traceback (most recent call last):
  File "/home/xiaozhiqi/blog_env/lib/python2.7/site-packages/django/core/handlers/base.py", line 132, in get_response
    response = wrapped_callback(request, *callback_args, **callback_kwargs)
  File "/home/xiaozhiqi/workplace/blog_project/blog/views.py", line 34, in index
    return render(request,'index.html',result)
  File "/home/xiaozhiqi/blog_env/lib/python2.7/site-packages/django/shortcuts.py", line 67, in render
    template_name, context, request=request, using=using)
  File "/home/xiaozhiqi/blog_env/lib/python2.7/site-packages/django/template/loader.py", line 99, in render_to_string
    return template.render(context, request)
  File "/home/xiaozhiqi/blog_env/lib/python2.7/site-packages/django/template/backends/django.py", line 74, in render
    return self.template.render(context)
  File "/home/xiaozhiqi/blog_env/lib/python2.7/site-packages/django/template/base.py", line 209, in render
    return self._render(context)
  File "/home/xiaozhiqi/blog_env/lib/python2.7/site-packages/django/template/base.py", line 201, in _render
    return self.nodelist.render(context)
  File "/home/xiaozhiqi/blog_env/lib/python2.7/site-packages/django/template/base.py", line 903, in render
    bit = self.render_node(node, context)
  File "/home/xiaozhiqi/blog_env/lib/python2.7/site-packages/django/template/debug.py", line 79, in render_node
    return node.render(context)
  File "/home/xiaozhiqi/blog_env/lib/python2.7/site-packages/django/template/loader_tags.py", line 135, in render
    return compiled_parent._render(context)
  File "/home/xiaozhiqi/blog_env/lib/python2.7/site-packages/django/template/base.py", line 201, in _render
    return self.nodelist.render(context)
  File "/home/xiaozhiqi/blog_env/lib/python2.7/site-packages/django/template/base.py", line 903, in render
    bit = self.render_node(node, context)
  File "/home/xiaozhiqi/blog_env/lib/python2.7/site-packages/django/template/debug.py", line 79, in render_node
    return node.render(context)
  File "/home/xiaozhiqi/blog_env/lib/python2.7/site-packages/django/template/loader_tags.py", line 65, in render
    result = block.nodelist.render(context)
  File "/home/xiaozhiqi/blog_env/lib/python2.7/site-packages/django/template/base.py", line 903, in render
    bit = self.render_node(node, context)
  File "/home/xiaozhiqi/blog_env/lib/python2.7/site-packages/django/template/debug.py", line 79, in render_node
    return node.render(context)
  File "/home/xiaozhiqi/blog_env/lib/python2.7/site-packages/django/template/loader_tags.py", line 151, in render
    template = context.template.engine.get_template(template)
  File "/home/xiaozhiqi/blog_env/lib/python2.7/site-packages/django/template/engine.py", line 167, in get_template
    template, origin = self.find_template(template_name, dirs)
  File "/home/xiaozhiqi/blog_env/lib/python2.7/site-packages/django/template/engine.py", line 141, in find_template
    source, display_name = loader(name, dirs)
  File "/home/xiaozhiqi/blog_env/lib/python2.7/site-packages/django/template/loaders/base.py", line 13, in __call__
    return self.load_template(template_name, template_dirs)
  File "/home/xiaozhiqi/blog_env/lib/python2.7/site-packages/django/template/loaders/base.py", line 23, in load_template
    template = Template(source, origin, template_name, self.engine)
  File "/home/xiaozhiqi/blog_env/lib/python2.7/site-packages/django/template/base.py", line 190, in __init__
    self.nodelist = engine.compile_string(template_string, origin)
  File "/home/xiaozhiqi/blog_env/lib/python2.7/site-packages/django/template/engine.py", line 261, in compile_string
    return parser.parse()
  File "/home/xiaozhiqi/blog_env/lib/python2.7/site-packages/django/template/base.py", line 341, in parse
    compiled_result = compile_func(self, token)
  File "/home/xiaozhiqi/blog_env/lib/python2.7/site-packages/django/template/defaulttags.py", line 872, in do_for
    nodelist_loop = parser.parse(('empty', 'endfor',))
  File "/home/xiaozhiqi/blog_env/lib/python2.7/site-packages/django/template/base.py", line 339, in parse
    self.invalid_block_tag(token, command, parse_until)
  File "/home/xiaozhiqi/blog_env/lib/python2.7/site-packages/django/template/base.py", line 394, in invalid_block_tag
    (command, get_text_list(["'%s'" % p for p in parse_until])))
TemplateSyntaxError: Invalid block tag: 'uploads', expected 'empty' or 'endfor'
2016-07-10 22:12:03,645 [Thread-68:139784860718848] [django.request:256] [base:handle_uncaught_exception] [ERROR]- Internal Server Error: /
Traceback (most recent call last):
  File "/home/xiaozhiqi/blog_env/lib/python2.7/site-packages/django/core/handlers/base.py", line 132, in get_response
    response = wrapped_callback(request, *callback_args, **callback_kwargs)
  File "/home/xiaozhiqi/workplace/blog_project/blog/views.py", line 34, in index
    return render(request,'index.html',result)
  File "/home/xiaozhiqi/blog_env/lib/python2.7/site-packages/django/shortcuts.py", line 67, in render
    template_name, context, request=request, using=using)
  File "/home/xiaozhiqi/blog_env/lib/python2.7/site-packages/django/template/loader.py", line 99, in render_to_string
    return template.render(context, request)
  File "/home/xiaozhiqi/blog_env/lib/python2.7/site-packages/django/template/backends/django.py", line 74, in render
    return self.template.render(context)
  File "/home/xiaozhiqi/blog_env/lib/python2.7/site-packages/django/template/base.py", line 209, in render
    return self._render(context)
  File "/home/xiaozhiqi/blog_env/lib/python2.7/site-packages/django/template/base.py", line 201, in _render
    return self.nodelist.render(context)
  File "/home/xiaozhiqi/blog_env/lib/python2.7/site-packages/django/template/base.py", line 903, in render
    bit = self.render_node(node, context)
  File "/home/xiaozhiqi/blog_env/lib/python2.7/site-packages/django/template/debug.py", line 79, in render_node
    return node.render(context)
  File "/home/xiaozhiqi/blog_env/lib/python2.7/site-packages/django/template/loader_tags.py", line 135, in render
    return compiled_parent._render(context)
  File "/home/xiaozhiqi/blog_env/lib/python2.7/site-packages/django/template/base.py", line 201, in _render
    return self.nodelist.render(context)
  File "/home/xiaozhiqi/blog_env/lib/python2.7/site-packages/django/template/base.py", line 903, in render
    bit = self.render_node(node, context)
  File "/home/xiaozhiqi/blog_env/lib/python2.7/site-packages/django/template/debug.py", line 79, in render_node
    return node.render(context)
  File "/home/xiaozhiqi/blog_env/lib/python2.7/site-packages/django/template/loader_tags.py", line 65, in render
    result = block.nodelist.render(context)
  File "/home/xiaozhiqi/blog_env/lib/python2.7/site-packages/django/template/base.py", line 903, in render
    bit = self.render_node(node, context)
  File "/home/xiaozhiqi/blog_env/lib/python2.7/site-packages/django/template/debug.py", line 79, in render_node
    return node.render(context)
  File "/home/xiaozhiqi/blog_env/lib/python2.7/site-packages/django/template/loader_tags.py", line 151, in render
    template = context.template.engine.get_template(template)
  File "/home/xiaozhiqi/blog_env/lib/python2.7/site-packages/django/template/engine.py", line 167, in get_template
    template, origin = self.find_template(template_name, dirs)
  File "/home/xiaozhiqi/blog_env/lib/python2.7/site-packages/django/template/engine.py", line 141, in find_template
    source, display_name = loader(name, dirs)
  File "/home/xiaozhiqi/blog_env/lib/python2.7/site-packages/django/template/loaders/base.py", line 13, in __call__
    return self.load_template(template_name, template_dirs)
  File "/home/xiaozhiqi/blog_env/lib/python2.7/site-packages/django/template/loaders/base.py", line 23, in load_template
    template = Template(source, origin, template_name, self.engine)
  File "/home/xiaozhiqi/blog_env/lib/python2.7/site-packages/django/template/base.py", line 190, in __init__
    self.nodelist = engine.compile_string(template_string, origin)
  File "/home/xiaozhiqi/blog_env/lib/python2.7/site-packages/django/template/engine.py", line 261, in compile_string
    return parser.parse()
  File "/home/xiaozhiqi/blog_env/lib/python2.7/site-packages/django/template/base.py", line 341, in parse
    compiled_result = compile_func(self, token)
  File "/home/xiaozhiqi/blog_env/lib/python2.7/site-packages/django/template/defaulttags.py", line 872, in do_for
    nodelist_loop = parser.parse(('empty', 'endfor',))
  File "/home/xiaozhiqi/blog_env/lib/python2.7/site-packages/django/template/base.py", line 341, in parse
    compiled_result = compile_func(self, token)
  File "/home/xiaozhiqi/blog_env/lib/python2.7/site-packages/django/contrib/staticfiles/templatetags/staticfiles.py", line 37, in do_static
    return StaticFilesNode.handle_token(parser, token)
  File "/home/xiaozhiqi/blog_env/lib/python2.7/site-packages/django/templatetags/static.py", line 126, in handle_token
    path = parser.compile_filter(bits[1])
  File "/home/xiaozhiqi/blog_env/lib/python2.7/site-packages/django/template/base.py", line 423, in compile_filter
    return FilterExpression(token, self)
  File "/home/xiaozhiqi/blog_env/lib/python2.7/site-packages/django/template/base.py", line 639, in __init__
    "from '%s'" % (token[upto:], token))
TemplateSyntaxError: Could not parse the remainder: '{{' from '{{'
2016-07-10 22:18:38,782 [Thread-102:139784878028544] [django.request:170] [base:get_response] [WARNING]- Not Found: /ad/2016/07/a1.jpg
2016-07-10 22:18:38,807 [Thread-103:139784878028544] [django.request:170] [base:get_response] [WARNING]- Not Found: /ad/2016/07/a2.jpg
2016-07-10 22:18:38,819 [Thread-105:139784843933440] [django.request:170] [base:get_response] [WARNING]- Not Found: /ad/2016/07/a4.jpg
2016-07-10 22:18:38,824 [Thread-104:139784835540736] [django.request:170] [base:get_response] [WARNING]- Not Found: /ad/2016/07/a3.jpg
2016-07-10 22:25:19,242 [Thread-122:139784860718848] [django.request:170] [base:get_response] [WARNING]- Not Found: /ad/2016/07/a1.jpg
2016-07-10 22:25:19,269 [Thread-123:139784860718848] [django.request:170] [base:get_response] [WARNING]- Not Found: /ad/2016/07/a2.jpg
2016-07-10 22:25:19,282 [Thread-124:139784878028544] [django.request:170] [base:get_response] [WARNING]- Not Found: /ad/2016/07/a3.jpg
2016-07-10 22:25:19,284 [Thread-125:139784843933440] [django.request:170] [base:get_response] [WARNING]- Not Found: /ad/2016/07/a4.jpg
2016-07-10 23:26:14,451 [Thread-33:140612902004480] [django.request:170] [base:get_response] [WARNING]- Not Found: /index.html
2016-07-11 14:11:51,596 [Thread-2:139937610508032] [django.request:256] [base:handle_uncaught_exception] [ERROR]- Internal Server Error: /
Traceback (most recent call last):
  File "/home/xiaozhiqi/blog_env/lib/python2.7/site-packages/django/core/handlers/base.py", line 119, in get_response
    resolver_match = resolver.resolve(request.path_info)
  File "/home/xiaozhiqi/blog_env/lib/python2.7/site-packages/django/core/urlresolvers.py", line 366, in resolve
    for pattern in self.url_patterns:
  File "/home/xiaozhiqi/blog_env/lib/python2.7/site-packages/django/core/urlresolvers.py", line 402, in url_patterns
    patterns = getattr(self.urlconf_module, "urlpatterns", self.urlconf_module)
  File "/home/xiaozhiqi/blog_env/lib/python2.7/site-packages/django/core/urlresolvers.py", line 396, in urlconf_module
    self._urlconf_module = import_module(self.urlconf_name)
  File "/home/xiaozhiqi/.pyenv/versions/2.7.11/lib/python2.7/importlib/__init__.py", line 37, in import_module
    __import__(name)
  File "/home/xiaozhiqi/workplace/blog_project/blog_project/urls.py", line 19, in <module>
    from blog import views
  File "/home/xiaozhiqi/workplace/blog_project/blog/views.py", line 57
    print Article.objects.distinct_date():
                                         ^
SyntaxError: invalid syntax
2016-07-11 14:16:00,720 [Thread-2:140326111016704] [django.request:256] [base:handle_uncaught_exception] [ERROR]- Internal Server Error: /
Traceback (most recent call last):
  File "/home/xiaozhiqi/blog_env/lib/python2.7/site-packages/django/core/handlers/base.py", line 119, in get_response
    resolver_match = resolver.resolve(request.path_info)
  File "/home/xiaozhiqi/blog_env/lib/python2.7/site-packages/django/core/urlresolvers.py", line 366, in resolve
    for pattern in self.url_patterns:
  File "/home/xiaozhiqi/blog_env/lib/python2.7/site-packages/django/core/urlresolvers.py", line 402, in url_patterns
    patterns = getattr(self.urlconf_module, "urlpatterns", self.urlconf_module)
  File "/home/xiaozhiqi/blog_env/lib/python2.7/site-packages/django/core/urlresolvers.py", line 396, in urlconf_module
    self._urlconf_module = import_module(self.urlconf_name)
  File "/home/xiaozhiqi/.pyenv/versions/2.7.11/lib/python2.7/importlib/__init__.py", line 37, in import_module
    __import__(name)
  File "/home/xiaozhiqi/workplace/blog_project/blog_project/urls.py", line 19, in <module>
    from blog import views
  File "/home/xiaozhiqi/workplace/blog_project/blog/views.py", line 57
    archive_list Article.objects.distinct_date()
                       ^
SyntaxError: invalid syntax
2016-07-11 15:15:09,164 [Thread-4:139748121171712] [django.request:170] [base:get_response] [WARNING]- Not Found: /favicon.ico
2016-07-11 15:15:09,181 [Thread-5:139748121171712] [django.request:170] [base:get_response] [WARNING]- Not Found: /favicon.ico
2016-07-11 16:11:25,679 [Thread-250:140346387564288] [django.request:256] [base:handle_uncaught_exception] [ERROR]- Internal Server Error: /
Traceback (most recent call last):
  File "/home/xiaozhiqi/blog_env/lib/python2.7/site-packages/django/core/handlers/base.py", line 132, in get_response
    response = wrapped_callback(request, *callback_args, **callback_kwargs)
  File "/home/xiaozhiqi/workplace/blog_project/blog/views.py", line 62, in index
    return render(request,'index.html',locals())   #locals()把当前所有的变量传给前端
  File "/home/xiaozhiqi/blog_env/lib/python2.7/site-packages/django/shortcuts.py", line 67, in render
    template_name, context, request=request, using=using)
  File "/home/xiaozhiqi/blog_env/lib/python2.7/site-packages/django/template/loader.py", line 99, in render_to_string
    return template.render(context, request)
  File "/home/xiaozhiqi/blog_env/lib/python2.7/site-packages/django/template/backends/django.py", line 74, in render
    return self.template.render(context)
  File "/home/xiaozhiqi/blog_env/lib/python2.7/site-packages/django/template/base.py", line 209, in render
    return self._render(context)
  File "/home/xiaozhiqi/blog_env/lib/python2.7/site-packages/django/template/base.py", line 201, in _render
    return self.nodelist.render(context)
  File "/home/xiaozhiqi/blog_env/lib/python2.7/site-packages/django/template/base.py", line 903, in render
    bit = self.render_node(node, context)
  File "/home/xiaozhiqi/blog_env/lib/python2.7/site-packages/django/template/debug.py", line 79, in render_node
    return node.render(context)
  File "/home/xiaozhiqi/blog_env/lib/python2.7/site-packages/django/template/loader_tags.py", line 135, in render
    return compiled_parent._render(context)
  File "/home/xiaozhiqi/blog_env/lib/python2.7/site-packages/django/template/base.py", line 201, in _render
    return self.nodelist.render(context)
  File "/home/xiaozhiqi/blog_env/lib/python2.7/site-packages/django/template/base.py", line 903, in render
    bit = self.render_node(node, context)
  File "/home/xiaozhiqi/blog_env/lib/python2.7/site-packages/django/template/debug.py", line 79, in render_node
    return node.render(context)
  File "/home/xiaozhiqi/blog_env/lib/python2.7/site-packages/django/template/loader_tags.py", line 65, in render
    result = block.nodelist.render(context)
  File "/home/xiaozhiqi/blog_env/lib/python2.7/site-packages/django/template/base.py", line 903, in render
    bit = self.render_node(node, context)
  File "/home/xiaozhiqi/blog_env/lib/python2.7/site-packages/django/template/debug.py", line 79, in render_node
    return node.render(context)
  File "/home/xiaozhiqi/blog_env/lib/python2.7/site-packages/django/template/defaulttags.py", line 217, in render
    nodelist.append(node.render(context))
  File "/home/xiaozhiqi/blog_env/lib/python2.7/site-packages/django/template/defaulttags.py", line 507, in render
    six.reraise(*exc_info)
  File "/home/xiaozhiqi/blog_env/lib/python2.7/site-packages/django/template/defaulttags.py", line 493, in render
    url = reverse(view_name, args=args, kwargs=kwargs, current_app=current_app)
  File "/home/xiaozhiqi/blog_env/lib/python2.7/site-packages/django/core/urlresolvers.py", line 579, in reverse
    return force_text(iri_to_uri(resolver._reverse_with_prefix(view, prefix, *args, **kwargs)))
  File "/home/xiaozhiqi/blog_env/lib/python2.7/site-packages/django/core/urlresolvers.py", line 496, in _reverse_with_prefix
    (lookup_view_s, args, kwargs, len(patterns), patterns))
NoReverseMatch: Reverse for 'article' with arguments '()' and keyword arguments '{}' not found. 0 pattern(s) tried: []
2016-07-11 16:11:27,279 [Thread-251:140346413790976] [django.request:256] [base:handle_uncaught_exception] [ERROR]- Internal Server Error: /
Traceback (most recent call last):
  File "/home/xiaozhiqi/blog_env/lib/python2.7/site-packages/django/core/handlers/base.py", line 132, in get_response
    response = wrapped_callback(request, *callback_args, **callback_kwargs)
  File "/home/xiaozhiqi/workplace/blog_project/blog/views.py", line 62, in index
    return render(request,'index.html',locals())   #locals()把当前所有的变量传给前端
  File "/home/xiaozhiqi/blog_env/lib/python2.7/site-packages/django/shortcuts.py", line 67, in render
    template_name, context, request=request, using=using)
  File "/home/xiaozhiqi/blog_env/lib/python2.7/site-packages/django/template/loader.py", line 99, in render_to_string
    return template.render(context, request)
  File "/home/xiaozhiqi/blog_env/lib/python2.7/site-packages/django/template/backends/django.py", line 74, in render
    return self.template.render(context)
  File "/home/xiaozhiqi/blog_env/lib/python2.7/site-packages/django/template/base.py", line 209, in render
    return self._render(context)
  File "/home/xiaozhiqi/blog_env/lib/python2.7/site-packages/django/template/base.py", line 201, in _render
    return self.nodelist.render(context)
  File "/home/xiaozhiqi/blog_env/lib/python2.7/site-packages/django/template/base.py", line 903, in render
    bit = self.render_node(node, context)
  File "/home/xiaozhiqi/blog_env/lib/python2.7/site-packages/django/template/debug.py", line 79, in render_node
    return node.render(context)
  File "/home/xiaozhiqi/blog_env/lib/python2.7/site-packages/django/template/loader_tags.py", line 135, in render
    return compiled_parent._render(context)
  File "/home/xiaozhiqi/blog_env/lib/python2.7/site-packages/django/template/base.py", line 201, in _render
    return self.nodelist.render(context)
  File "/home/xiaozhiqi/blog_env/lib/python2.7/site-packages/django/template/base.py", line 903, in render
    bit = self.render_node(node, context)
  File "/home/xiaozhiqi/blog_env/lib/python2.7/site-packages/django/template/debug.py", line 79, in render_node
    return node.render(context)
  File "/home/xiaozhiqi/blog_env/lib/python2.7/site-packages/django/template/loader_tags.py", line 65, in render
    result = block.nodelist.render(context)
  File "/home/xiaozhiqi/blog_env/lib/python2.7/site-packages/django/template/base.py", line 903, in render
    bit = self.render_node(node, context)
  File "/home/xiaozhiqi/blog_env/lib/python2.7/site-packages/django/template/debug.py", line 79, in render_node
    return node.render(context)
  File "/home/xiaozhiqi/blog_env/lib/python2.7/site-packages/django/template/defaulttags.py", line 217, in render
    nodelist.append(node.render(context))
  File "/home/xiaozhiqi/blog_env/lib/python2.7/site-packages/django/template/defaulttags.py", line 507, in render
    six.reraise(*exc_info)
  File "/home/xiaozhiqi/blog_env/lib/python2.7/site-packages/django/template/defaulttags.py", line 493, in render
    url = reverse(view_name, args=args, kwargs=kwargs, current_app=current_app)
  File "/home/xiaozhiqi/blog_env/lib/python2.7/site-packages/django/core/urlresolvers.py", line 579, in reverse
    return force_text(iri_to_uri(resolver._reverse_with_prefix(view, prefix, *args, **kwargs)))
  File "/home/xiaozhiqi/blog_env/lib/python2.7/site-packages/django/core/urlresolvers.py", line 496, in _reverse_with_prefix
    (lookup_view_s, args, kwargs, len(patterns), patterns))
NoReverseMatch: Reverse for 'article' with arguments '()' and keyword arguments '{}' not found. 0 pattern(s) tried: []
2016-07-11 16:30:51,749 [Thread-2:140037238724352] [django.request:256] [base:handle_uncaught_exception] [ERROR]- Internal Server Error: /
Traceback (most recent call last):
  File "/home/xiaozhiqi/blog_env/lib/python2.7/site-packages/django/core/handlers/base.py", line 119, in get_response
    resolver_match = resolver.resolve(request.path_info)
  File "/home/xiaozhiqi/blog_env/lib/python2.7/site-packages/django/core/urlresolvers.py", line 366, in resolve
    for pattern in self.url_patterns:
  File "/home/xiaozhiqi/blog_env/lib/python2.7/site-packages/django/core/urlresolvers.py", line 402, in url_patterns
    patterns = getattr(self.urlconf_module, "urlpatterns", self.urlconf_module)
  File "/home/xiaozhiqi/blog_env/lib/python2.7/site-packages/django/core/urlresolvers.py", line 396, in urlconf_module
    self._urlconf_module = import_module(self.urlconf_name)
  File "/home/xiaozhiqi/.pyenv/versions/2.7.11/lib/python2.7/importlib/__init__.py", line 37, in import_module
    __import__(name)
  File "/home/xiaozhiqi/workplace/blog_project/blog_project/urls.py", line 19, in <module>
    from blog import views
  File "/home/xiaozhiqi/workplace/blog_project/blog/views.py", line 72
    article_list = Article.objects.filter(date_publish__icontains=year+'-'month)  # 获取所有数据
                                                                              ^
SyntaxError: invalid syntax
2016-07-11 16:33:32,117 [Thread-105:140037220890368] [django.request:170] [base:get_response] [WARNING]- Not Found: /index.html
2016-07-11 16:34:02,009 [Thread-113:140036997637888] [django.request:170] [base:get_response] [WARNING]- Not Found: /index.html
2016-07-12 11:00:25,413 [Thread-2:140651841369856] [django.request:256] [base:handle_uncaught_exception] [ERROR]- Internal Server Error: /
Traceback (most recent call last):
  File "/home/xiaozhiqi/blog_env/lib/python2.7/site-packages/django/core/handlers/base.py", line 119, in get_response
    resolver_match = resolver.resolve(request.path_info)
  File "/home/xiaozhiqi/blog_env/lib/python2.7/site-packages/django/core/urlresolvers.py", line 366, in resolve
    for pattern in self.url_patterns:
  File "/home/xiaozhiqi/blog_env/lib/python2.7/site-packages/django/core/urlresolvers.py", line 402, in url_patterns
    patterns = getattr(self.urlconf_module, "urlpatterns", self.urlconf_module)
  File "/home/xiaozhiqi/blog_env/lib/python2.7/site-packages/django/core/urlresolvers.py", line 396, in urlconf_module
    self._urlconf_module = import_module(self.urlconf_name)
  File "/home/xiaozhiqi/.pyenv/versions/2.7.11/lib/python2.7/importlib/__init__.py", line 37, in import_module
    __import__(name)
  File "/home/xiaozhiqi/workplace/blog_project/blog_project/urls.py", line 10
SyntaxError: Non-ASCII character '\xe9' in file /home/xiaozhiqi/workplace/blog_project/blog_project/urls.py on line 10, but no encoding declared; see http://python.org/dev/peps/pep-0263/ for details
2016-07-12 11:00:26,478 [Thread-3:140651832977152] [django.request:256] [base:handle_uncaught_exception] [ERROR]- Internal Server Error: /
Traceback (most recent call last):
  File "/home/xiaozhiqi/blog_env/lib/python2.7/site-packages/django/core/handlers/base.py", line 119, in get_response
    resolver_match = resolver.resolve(request.path_info)
  File "/home/xiaozhiqi/blog_env/lib/python2.7/site-packages/django/core/urlresolvers.py", line 366, in resolve
    for pattern in self.url_patterns:
  File "/home/xiaozhiqi/blog_env/lib/python2.7/site-packages/django/core/urlresolvers.py", line 402, in url_patterns
    patterns = getattr(self.urlconf_module, "urlpatterns", self.urlconf_module)
  File "/home/xiaozhiqi/blog_env/lib/python2.7/site-packages/django/core/urlresolvers.py", line 396, in urlconf_module
    self._urlconf_module = import_module(self.urlconf_name)
  File "/home/xiaozhiqi/.pyenv/versions/2.7.11/lib/python2.7/importlib/__init__.py", line 37, in import_module
    __import__(name)
  File "/home/xiaozhiqi/workplace/blog_project/blog_project/urls.py", line 10
SyntaxError: Non-ASCII character '\xe9' in file /home/xiaozhiqi/workplace/blog_project/blog_project/urls.py on line 10, but no encoding declared; see http://python.org/dev/peps/pep-0263/ for details
2016-07-12 11:00:27,330 [Thread-4:140651824584448] [django.request:256] [base:handle_uncaught_exception] [ERROR]- Internal Server Error: /
Traceback (most recent call last):
  File "/home/xiaozhiqi/blog_env/lib/python2.7/site-packages/django/core/handlers/base.py", line 119, in get_response
    resolver_match = resolver.resolve(request.path_info)
  File "/home/xiaozhiqi/blog_env/lib/python2.7/site-packages/django/core/urlresolvers.py", line 366, in resolve
    for pattern in self.url_patterns:
  File "/home/xiaozhiqi/blog_env/lib/python2.7/site-packages/django/core/urlresolvers.py", line 402, in url_patterns
    patterns = getattr(self.urlconf_module, "urlpatterns", self.urlconf_module)
  File "/home/xiaozhiqi/blog_env/lib/python2.7/site-packages/django/core/urlresolvers.py", line 396, in urlconf_module
    self._urlconf_module = import_module(self.urlconf_name)
  File "/home/xiaozhiqi/.pyenv/versions/2.7.11/lib/python2.7/importlib/__init__.py", line 37, in import_module
    __import__(name)
  File "/home/xiaozhiqi/workplace/blog_project/blog_project/urls.py", line 10
SyntaxError: Non-ASCII character '\xe9' in file /home/xiaozhiqi/workplace/blog_project/blog_project/urls.py on line 10, but no encoding declared; see http://python.org/dev/peps/pep-0263/ for details
2016-07-12 11:00:27,945 [Thread-5:140651816191744] [django.request:256] [base:handle_uncaught_exception] [ERROR]- Internal Server Error: /
Traceback (most recent call last):
  File "/home/xiaozhiqi/blog_env/lib/python2.7/site-packages/django/core/handlers/base.py", line 119, in get_response
    resolver_match = resolver.resolve(request.path_info)
  File "/home/xiaozhiqi/blog_env/lib/python2.7/site-packages/django/core/urlresolvers.py", line 366, in resolve
    for pattern in self.url_patterns:
  File "/home/xiaozhiqi/blog_env/lib/python2.7/site-packages/django/core/urlresolvers.py", line 402, in url_patterns
    patterns = getattr(self.urlconf_module, "urlpatterns", self.urlconf_module)
  File "/home/xiaozhiqi/blog_env/lib/python2.7/site-packages/django/core/urlresolvers.py", line 396, in urlconf_module
    self._urlconf_module = import_module(self.urlconf_name)
  File "/home/xiaozhiqi/.pyenv/versions/2.7.11/lib/python2.7/importlib/__init__.py", line 37, in import_module
    __import__(name)
  File "/home/xiaozhiqi/workplace/blog_project/blog_project/urls.py", line 10
SyntaxError: Non-ASCII character '\xe9' in file /home/xiaozhiqi/workplace/blog_project/blog_project/urls.py on line 10, but no encoding declared; see http://python.org/dev/peps/pep-0263/ for details
2016-07-12 11:01:11,230 [Thread-2:140542525531904] [django.request:256] [base:handle_uncaught_exception] [ERROR]- Internal Server Error: /
Traceback (most recent call last):
  File "/home/xiaozhiqi/blog_env/lib/python2.7/site-packages/django/core/handlers/base.py", line 119, in get_response
    resolver_match = resolver.resolve(request.path_info)
  File "/home/xiaozhiqi/blog_env/lib/python2.7/site-packages/django/core/urlresolvers.py", line 366, in resolve
    for pattern in self.url_patterns:
  File "/home/xiaozhiqi/blog_env/lib/python2.7/site-packages/django/core/urlresolvers.py", line 402, in url_patterns
    patterns = getattr(self.urlconf_module, "urlpatterns", self.urlconf_module)
  File "/home/xiaozhiqi/blog_env/lib/python2.7/site-packages/django/core/urlresolvers.py", line 396, in urlconf_module
    self._urlconf_module = import_module(self.urlconf_name)
  File "/home/xiaozhiqi/.pyenv/versions/2.7.11/lib/python2.7/importlib/__init__.py", line 37, in import_module
    __import__(name)
  File "/home/xiaozhiqi/workplace/blog_project/blog_project/urls.py", line 10
SyntaxError: Non-ASCII character '\xe9' in file /home/xiaozhiqi/workplace/blog_project/blog_project/urls.py on line 10, but no encoding declared; see http://python.org/dev/peps/pep-0263/ for details
2016-07-12 11:01:12,090 [Thread-3:140542516877056] [django.request:256] [base:handle_uncaught_exception] [ERROR]- Internal Server Error: /
Traceback (most recent call last):
  File "/home/xiaozhiqi/blog_env/lib/python2.7/site-packages/django/core/handlers/base.py", line 119, in get_response
    resolver_match = resolver.resolve(request.path_info)
  File "/home/xiaozhiqi/blog_env/lib/python2.7/site-packages/django/core/urlresolvers.py", line 366, in resolve
    for pattern in self.url_patterns:
  File "/home/xiaozhiqi/blog_env/lib/python2.7/site-packages/django/core/urlresolvers.py", line 402, in url_patterns
    patterns = getattr(self.urlconf_module, "urlpatterns", self.urlconf_module)
  File "/home/xiaozhiqi/blog_env/lib/python2.7/site-packages/django/core/urlresolvers.py", line 396, in urlconf_module
    self._urlconf_module = import_module(self.urlconf_name)
  File "/home/xiaozhiqi/.pyenv/versions/2.7.11/lib/python2.7/importlib/__init__.py", line 37, in import_module
    __import__(name)
  File "/home/xiaozhiqi/workplace/blog_project/blog_project/urls.py", line 10
SyntaxError: Non-ASCII character '\xe9' in file /home/xiaozhiqi/workplace/blog_project/blog_project/urls.py on line 10, but no encoding declared; see http://python.org/dev/peps/pep-0263/ for details
2016-07-12 11:01:12,775 [Thread-4:140542508484352] [django.request:256] [base:handle_uncaught_exception] [ERROR]- Internal Server Error: /
Traceback (most recent call last):
  File "/home/xiaozhiqi/blog_env/lib/python2.7/site-packages/django/core/handlers/base.py", line 119, in get_response
    resolver_match = resolver.resolve(request.path_info)
  File "/home/xiaozhiqi/blog_env/lib/python2.7/site-packages/django/core/urlresolvers.py", line 366, in resolve
    for pattern in self.url_patterns:
  File "/home/xiaozhiqi/blog_env/lib/python2.7/site-packages/django/core/urlresolvers.py", line 402, in url_patterns
    patterns = getattr(self.urlconf_module, "urlpatterns", self.urlconf_module)
  File "/home/xiaozhiqi/blog_env/lib/python2.7/site-packages/django/core/urlresolvers.py", line 396, in urlconf_module
    self._urlconf_module = import_module(self.urlconf_name)
  File "/home/xiaozhiqi/.pyenv/versions/2.7.11/lib/python2.7/importlib/__init__.py", line 37, in import_module
    __import__(name)
  File "/home/xiaozhiqi/workplace/blog_project/blog_project/urls.py", line 10
SyntaxError: Non-ASCII character '\xe9' in file /home/xiaozhiqi/workplace/blog_project/blog_project/urls.py on line 10, but no encoding declared; see http://python.org/dev/peps/pep-0263/ for details
2016-07-12 11:01:13,416 [Thread-5:140542508484352] [django.request:256] [base:handle_uncaught_exception] [ERROR]- Internal Server Error: /
Traceback (most recent call last):
  File "/home/xiaozhiqi/blog_env/lib/python2.7/site-packages/django/core/handlers/base.py", line 119, in get_response
    resolver_match = resolver.resolve(request.path_info)
  File "/home/xiaozhiqi/blog_env/lib/python2.7/site-packages/django/core/urlresolvers.py", line 366, in resolve
    for pattern in self.url_patterns:
  File "/home/xiaozhiqi/blog_env/lib/python2.7/site-packages/django/core/urlresolvers.py", line 402, in url_patterns
    patterns = getattr(self.urlconf_module, "urlpatterns", self.urlconf_module)
  File "/home/xiaozhiqi/blog_env/lib/python2.7/site-packages/django/core/urlresolvers.py", line 396, in urlconf_module
    self._urlconf_module = import_module(self.urlconf_name)
  File "/home/xiaozhiqi/.pyenv/versions/2.7.11/lib/python2.7/importlib/__init__.py", line 37, in import_module
    __import__(name)
  File "/home/xiaozhiqi/workplace/blog_project/blog_project/urls.py", line 10
SyntaxError: Non-ASCII character '\xe9' in file /home/xiaozhiqi/workplace/blog_project/blog_project/urls.py on line 10, but no encoding declared; see http://python.org/dev/peps/pep-0263/ for details
2016-07-12 11:01:13,633 [Thread-6:140542508484352] [django.request:256] [base:handle_uncaught_exception] [ERROR]- Internal Server Error: /
Traceback (most recent call last):
  File "/home/xiaozhiqi/blog_env/lib/python2.7/site-packages/django/core/handlers/base.py", line 119, in get_response
    resolver_match = resolver.resolve(request.path_info)
  File "/home/xiaozhiqi/blog_env/lib/python2.7/site-packages/django/core/urlresolvers.py", line 366, in resolve
    for pattern in self.url_patterns:
  File "/home/xiaozhiqi/blog_env/lib/python2.7/site-packages/django/core/urlresolvers.py", line 402, in url_patterns
    patterns = getattr(self.urlconf_module, "urlpatterns", self.urlconf_module)
  File "/home/xiaozhiqi/blog_env/lib/python2.7/site-packages/django/core/urlresolvers.py", line 396, in urlconf_module
    self._urlconf_module = import_module(self.urlconf_name)
  File "/home/xiaozhiqi/.pyenv/versions/2.7.11/lib/python2.7/importlib/__init__.py", line 37, in import_module
    __import__(name)
  File "/home/xiaozhiqi/workplace/blog_project/blog_project/urls.py", line 10
SyntaxError: Non-ASCII character '\xe9' in file /home/xiaozhiqi/workplace/blog_project/blog_project/urls.py on line 10, but no encoding declared; see http://python.org/dev/peps/pep-0263/ for details
2016-07-12 11:01:13,870 [Thread-7:140542508484352] [django.request:256] [base:handle_uncaught_exception] [ERROR]- Internal Server Error: /
Traceback (most recent call last):
  File "/home/xiaozhiqi/blog_env/lib/python2.7/site-packages/django/core/handlers/base.py", line 119, in get_response
    resolver_match = resolver.resolve(request.path_info)
  File "/home/xiaozhiqi/blog_env/lib/python2.7/site-packages/django/core/urlresolvers.py", line 366, in resolve
    for pattern in self.url_patterns:
  File "/home/xiaozhiqi/blog_env/lib/python2.7/site-packages/django/core/urlresolvers.py", line 402, in url_patterns
    patterns = getattr(self.urlconf_module, "urlpatterns", self.urlconf_module)
  File "/home/xiaozhiqi/blog_env/lib/python2.7/site-packages/django/core/urlresolvers.py", line 396, in urlconf_module
    self._urlconf_module = import_module(self.urlconf_name)
  File "/home/xiaozhiqi/.pyenv/versions/2.7.11/lib/python2.7/importlib/__init__.py", line 37, in import_module
    __import__(name)
  File "/home/xiaozhiqi/workplace/blog_project/blog_project/urls.py", line 10
SyntaxError: Non-ASCII character '\xe9' in file /home/xiaozhiqi/workplace/blog_project/blog_project/urls.py on line 10, but no encoding declared; see http://python.org/dev/peps/pep-0263/ for details
2016-07-12 11:01:14,081 [Thread-8:140542508484352] [django.request:256] [base:handle_uncaught_exception] [ERROR]- Internal Server Error: /
Traceback (most recent call last):
  File "/home/xiaozhiqi/blog_env/lib/python2.7/site-packages/django/core/handlers/base.py", line 119, in get_response
    resolver_match = resolver.resolve(request.path_info)
  File "/home/xiaozhiqi/blog_env/lib/python2.7/site-packages/django/core/urlresolvers.py", line 366, in resolve
    for pattern in self.url_patterns:
  File "/home/xiaozhiqi/blog_env/lib/python2.7/site-packages/django/core/urlresolvers.py", line 402, in url_patterns
    patterns = getattr(self.urlconf_module, "urlpatterns", self.urlconf_module)
  File "/home/xiaozhiqi/blog_env/lib/python2.7/site-packages/django/core/urlresolvers.py", line 396, in urlconf_module
    self._urlconf_module = import_module(self.urlconf_name)
  File "/home/xiaozhiqi/.pyenv/versions/2.7.11/lib/python2.7/importlib/__init__.py", line 37, in import_module
    __import__(name)
  File "/home/xiaozhiqi/workplace/blog_project/blog_project/urls.py", line 10
SyntaxError: Non-ASCII character '\xe9' in file /home/xiaozhiqi/workplace/blog_project/blog_project/urls.py on line 10, but no encoding declared; see http://python.org/dev/peps/pep-0263/ for details
2016-07-12 11:01:14,574 [Thread-9:140542508484352] [django.request:256] [base:handle_uncaught_exception] [ERROR]- Internal Server Error: /
Traceback (most recent call last):
  File "/home/xiaozhiqi/blog_env/lib/python2.7/site-packages/django/core/handlers/base.py", line 119, in get_response
    resolver_match = resolver.resolve(request.path_info)
  File "/home/xiaozhiqi/blog_env/lib/python2.7/site-packages/django/core/urlresolvers.py", line 366, in resolve
    for pattern in self.url_patterns:
  File "/home/xiaozhiqi/blog_env/lib/python2.7/site-packages/django/core/urlresolvers.py", line 402, in url_patterns
    patterns = getattr(self.urlconf_module, "urlpatterns", self.urlconf_module)
  File "/home/xiaozhiqi/blog_env/lib/python2.7/site-packages/django/core/urlresolvers.py", line 396, in urlconf_module
    self._urlconf_module = import_module(self.urlconf_name)
  File "/home/xiaozhiqi/.pyenv/versions/2.7.11/lib/python2.7/importlib/__init__.py", line 37, in import_module
    __import__(name)
  File "/home/xiaozhiqi/workplace/blog_project/blog_project/urls.py", line 10
SyntaxError: Non-ASCII character '\xe9' in file /home/xiaozhiqi/workplace/blog_project/blog_project/urls.py on line 10, but no encoding declared; see http://python.org/dev/peps/pep-0263/ for details
2016-07-12 11:01:36,531 [Thread-10:140542508484352] [django.request:256] [base:handle_uncaught_exception] [ERROR]- Internal Server Error: /
Traceback (most recent call last):
  File "/home/xiaozhiqi/blog_env/lib/python2.7/site-packages/django/core/handlers/base.py", line 119, in get_response
    resolver_match = resolver.resolve(request.path_info)
  File "/home/xiaozhiqi/blog_env/lib/python2.7/site-packages/django/core/urlresolvers.py", line 366, in resolve
    for pattern in self.url_patterns:
  File "/home/xiaozhiqi/blog_env/lib/python2.7/site-packages/django/core/urlresolvers.py", line 402, in url_patterns
    patterns = getattr(self.urlconf_module, "urlpatterns", self.urlconf_module)
  File "/home/xiaozhiqi/blog_env/lib/python2.7/site-packages/django/core/urlresolvers.py", line 396, in urlconf_module
    self._urlconf_module = import_module(self.urlconf_name)
  File "/home/xiaozhiqi/.pyenv/versions/2.7.11/lib/python2.7/importlib/__init__.py", line 37, in import_module
    __import__(name)
  File "/home/xiaozhiqi/workplace/blog_project/blog_project/urls.py", line 12, in <module>
    url(r'^', include(blog.urls)),
NameError: name 'blog' is not defined
2016-07-12 11:01:52,828 [Thread-11:140542508484352] [django.request:256] [base:handle_uncaught_exception] [ERROR]- Internal Server Error: /
Traceback (most recent call last):
  File "/home/xiaozhiqi/blog_env/lib/python2.7/site-packages/django/core/handlers/base.py", line 119, in get_response
    resolver_match = resolver.resolve(request.path_info)
  File "/home/xiaozhiqi/blog_env/lib/python2.7/site-packages/django/core/urlresolvers.py", line 366, in resolve
    for pattern in self.url_patterns:
  File "/home/xiaozhiqi/blog_env/lib/python2.7/site-packages/django/core/urlresolvers.py", line 402, in url_patterns
    patterns = getattr(self.urlconf_module, "urlpatterns", self.urlconf_module)
  File "/home/xiaozhiqi/blog_env/lib/python2.7/site-packages/django/core/urlresolvers.py", line 396, in urlconf_module
    self._urlconf_module = import_module(self.urlconf_name)
  File "/home/xiaozhiqi/.pyenv/versions/2.7.11/lib/python2.7/importlib/__init__.py", line 37, in import_module
    __import__(name)
  File "/home/xiaozhiqi/workplace/blog_project/blog_project/urls.py", line 12, in <module>
    url(r'^', include('blog.urls')),
  File "/home/xiaozhiqi/blog_env/lib/python2.7/site-packages/django/conf/urls/__init__.py", line 33, in include
    urlconf_module = import_module(urlconf_module)
  File "/home/xiaozhiqi/.pyenv/versions/2.7.11/lib/python2.7/importlib/__init__.py", line 37, in import_module
    __import__(name)
  File "/home/xiaozhiqi/workplace/blog_project/blog/urls.py", line 2, in <module>
    from blog.views import index,archive
  File "/home/xiaozhiqi/workplace/blog_project/blog/views.py", line 31
    comment_list = Comment.objects.all(article=)
                                               ^
SyntaxError: invalid syntax
